Workbook
Name Slicer_CURRENT_STOCK: #N/A
Name Slicer_FETCH_CATEGORY: #N/A
Name Slicer_FETCH_CATEGORY1: #N/A
Name Slicer_PRODUCT_NAME: #N/A
Name Slicer_PRODUCT_NAME1: #N/A
Name Slicer_PRODUCT_NAME2: #N/A

Sheet Stock Data 
A1: DATE | B1: PRODUCT ID | C1: PRODUCT NAME | D1: IN QUANTITY | E1: OUT QUANTITY | F1: CURRENT STOCK | G1: FETCH CATEGORY | H1: FETCH PRICE | I1: STOCK STATUS
A2: 46026 | B2: P001 | C2: Rice | D2: 100 | E2: 20 | F2: =D2-E2 -> 80 | G2: =VLOOKUP(B2,'Product Master'!A2:C11,2,FALSE) -> Grocery | H2: =INDEX('Product Master'!C2:C11,MATCH('Stock Data '!B2,'Product Master'!A2:A11,0)) -> 50 | I2: =IF(F2<20,"LOW STOCK","OK") -> OK
A3: 46026 | B3: P002 | C3: Sugar | D3: 80 | E3: 30 | F3: =D3-E3 -> 50 | G3: =VLOOKUP(B3,'Product Master'!A3:C12,2,FALSE) -> Grocery | H3: =INDEX('Product Master'!C3:C12,MATCH('Stock Data '!B3,'Product Master'!A3:A12,0)) -> 45 | I3: =IF(F3<20,"LOW STOCK","OK") -> OK
A4: 46026 | B4: P003 | C4: Oil | D4: 60 | E4: 10 | F4: =D4-E4 -> 50 | G4: =VLOOKUP(B4,'Product Master'!A4:C13,2,FALSE) -> Grocery | H4: =INDEX('Product Master'!C4:C13,MATCH('Stock Data '!B4,'Product Master'!A4:A13,0)) -> 120 | I4: =IF(F4<20,"LOW STOCK","OK") -> OK
A5: 46057 | B5: P004 | C5: Biscuit | D5: 90 | E5: 25 | F5: =D5-E5 -> 65 | G5: =VLOOKUP(B5,'Product Master'!A5:C14,2,FALSE) -> Snacks | H5: =INDEX('Product Master'!C5:C14,MATCH('Stock Data '!B5,'Product Master'!A5:A14,0)) -> 30 | I5: =IF(F5<20,"LOW STOCK","OK") -> OK
A6: 46057 | B6: P005 | C6: Juice | D6: 70 | E6: 15 | F6: =D6-E6 -> 55 | G6: =VLOOKUP(B6,'Product Master'!A6:C15,2,FALSE) -> Beverages | H6: =INDEX('Product Master'!C6:C15,MATCH('Stock Data '!B6,'Product Master'!A6:A15,0)) -> 60 | I6: =IF(F6<20,"LOW STOCK","OK") -> OK
A7: 46085 | B7: P006 | C7: Soap | D7: 120 | E7: 40 | F7: =D7-E7 -> 80 | G7: =VLOOKUP(B7,'Product Master'!A7:C16,2,FALSE) -> Personal Care | H7: =INDEX('Product Master'!C7:C16,MATCH('Stock Data '!B7,'Product Master'!A7:A16,0)) -> 40 | I7: =IF(F7<20,"LOW STOCK","OK") -> OK
A8: 46085 | B8: P007 | C8: Shampoo | D8: 85 | E8: 20 | F8: =D8-E8 -> 65 | G8: =VLOOKUP(B8,'Product Master'!A8:C17,2,FALSE) -> Personal Care | H8: =INDEX('Product Master'!C8:C17,MATCH('Stock Data '!B8,'Product Master'!A8:A17,0)) -> 150 | I8: =IF(F8<20,"LOW STOCK","OK") -> OK
A9: 46116 | B9: P008 | C9: Tea | D9: 75 | E9: 18 | F9: =D9-E9 -> 57 | G9: =VLOOKUP(B9,'Product Master'!A9:C18,2,FALSE) -> Grocery | H9: =INDEX('Product Master'!C9:C18,MATCH('Stock Data '!B9,'Product Master'!A9:A18,0)) -> 200 | I9: =IF(F9<20,"LOW STOCK","OK") -> OK
A10: 46116 | B10: P009 | C10: Coffee | D10: 65 | E10: 12 | F10: =D10-E10 -> 53 | G10: =VLOOKUP(B10,'Product Master'!A10:C19,2,FALSE) -> Grocery | H10: =INDEX('Product Master'!C10:C19,MATCH('Stock Data '!B10,'Product Master'!A10:A19,0)) -> 250 | I10: =IF(F10<20,"LOW STOCK","OK") -> OK
A11: 46146 | B11: P010 | C11: Milk | D11: 110 | E11: 50 | F11: =D11-E11 -> 60 | G11: =VLOOKUP(B11,'Product Master'!A11:C20,2,FALSE) -> Dairy | H11: =INDEX('Product Master'!C11:C20,MATCH('Stock Data '!B11,'Product Master'!A11:A20,0)) -> 35 | I11: =IF(F11<20,"LOW STOCK","OK") -> OK
A12: 46146 | B12: P001 | C12: Rice | D12: 90 | E12: 30 | F12: =D12-E12 -> 60 | G12: =VLOOKUP(B12,'Product Master'!A2:C11,2,FALSE) -> Grocery | H12: =INDEX('Product Master'!C2:C11,MATCH('Stock Data '!B12,'Product Master'!A2:A11,0)) -> 50 | I12: =IF(F12<20,"LOW STOCK","OK") -> OK
A13: 46177 | B13: P002 | C13: Sugar | D13: 70 | E13: 20 | F13: =D13-E13 -> 50 | G13: =VLOOKUP(B13,'Product Master'!A2:C11,2,FALSE) -> Grocery | H13: =INDEX('Product Master'!C2:C11,MATCH('Stock Data '!B13,'Product Master'!A2:A11,0)) -> 45 | I13: =IF(F13<20,"LOW STOCK","OK") -> OK
A14: 46177 | B14: P003 | C14: Oil | D14: 50 | E14: 15 | F14: =D14-E14 -> 35 | G14: =VLOOKUP(B14,'Product Master'!A2:C11,2,FALSE) -> Grocery | H14: =INDEX('Product Master'!C2:C11,MATCH('Stock Data '!B14,'Product Master'!A2:A11,0)) -> 120 | I14: =IF(F14<20,"LOW STOCK","OK") -> OK
A15: 46207 | B15: P004 | C15: Biscuit | D15: 80 | E15: 22 | F15: =D15-E15 -> 58 | G15: =VLOOKUP(B15,'Product Master'!A2:C11,2,FALSE) -> Snacks | H15: =INDEX('Product Master'!C2:C11,MATCH('Stock Data '!B15,'Product Master'!A2:A11,0)) -> 30 | I15: =IF(F15<20,"LOW STOCK","OK") -> OK
A16: 46207 | B16: P005 | C16: Juice | D16: 60 | E16: 18 | F16: =D16-E16 -> 42 | G16: =VLOOKUP(B16,'Product Master'!A2:C11,2,FALSE) -> Beverages | H16: =INDEX('Product Master'!C2:C11,MATCH('Stock Data '!B16,'Product Master'!A2:A11,0)) -> 60 | I16: =IF(F16<20,"LOW STOCK","OK") -> OK | K16: PROJECT 3: Inventory & Stock Management MIS
A17: 46238 | B17: P006 | C17: Soap | D17: 100 | E17: 35 | F17: =D17-E17 -> 65 | G17: =VLOOKUP(B17,'Product Master'!A2:C11,2,FALSE) -> Personal Care | H17: =INDEX('Product Master'!C2:C11,MATCH('Stock Data '!B17,'Product Master'!A2:A11,0)) -> 40 | I17: =IF(F17<20,"LOW STOCK","OK") -> OK
A18: 46238 | B18: P007 | C18: Shampoo | D18: 75 | E18: 25 | F18: =D18-E18 -> 50 | G18: =VLOOKUP(B18,'Product Master'!A2:C11,2,FALSE) -> Personal Care | H18: =INDEX('Product Master'!C2:C11,MATCH('Stock Data '!B18,'Product Master'!A2:A11,0)) -> 150 | I18: =IF(F18<20,"LOW STOCK","OK") -> OK
A19: 46269 | B19: P008 | C19: Tea | D19: 65 | E19: 20 | F19: =D19-E19 -> 45 | G19: =VLOOKUP(B19,'Product Master'!A2:C11,2,FALSE) -> Grocery | H19: =INDEX('Product Master'!C2:C11,MATCH('Stock Data '!B19,'Product Master'!A2:A11,0)) -> 200 | I19: =IF(F19<20,"LOW STOCK","OK") -> OK
A20: 46269 | B20: P009 | C20: Coffee | D20: 55 | E20: 15 | F20: =D20-E20 -> 40 | G20: =VLOOKUP(B20,'Product Master'!A2:C11,2,FALSE) -> Grocery | H20: =INDEX('Product Master'!C2:C11,MATCH('Stock Data '!B20,'Product Master'!A2:A11,0)) -> 250 | I20: =IF(F20<20,"LOW STOCK","OK") -> OK
A21: 46299 | B21: P010 | C21: Milk | D21: 95 | E21: 45 | F21: =D21-E21 -> 50 | G21: =VLOOKUP(B21,'Product Master'!A2:C11,2,FALSE) -> Dairy | H21: =INDEX('Product Master'!C2:C11,MATCH('Stock Data '!B21,'Product Master'!A2:A11,0)) -> 35 | I21: =IF(F21<20,"LOW STOCK","OK") -> OK
A22: 46299 | B22: P001 | C22: Rice | D22: 85 | E22: 25 | F22: =D22-E22 -> 60 | G22: =VLOOKUP(B22,'Product Master'!A2:C11,2,FALSE) -> Grocery | H22: =INDEX('Product Master'!C2:C11,MATCH('Stock Data '!B22,'Product Master'!A2:A11,0)) -> 50 | I22: =IF(F22<20,"LOW STOCK","OK") -> OK
A23: 46330 | B23: P002 | C23: Sugar | D23: 60 | E23: 18 | F23: =D23-E23 -> 42 | G23: =VLOOKUP(B23,'Product Master'!A2:C11,2,FALSE) -> Grocery | H23: =INDEX('Product Master'!C2:C11,MATCH('Stock Data '!B23,'Product Master'!A2:A11,0)) -> 45 | I23: =IF(F23<20,"LOW STOCK","OK") -> OK
A24: 46330 | B24: P003 | C24: Oil | D24: 45 | E24: 10 | F24: =D24-E24 -> 35 | G24: =VLOOKUP(B24,'Product Master'!A2:C11,2,FALSE) -> Grocery | H24: =INDEX('Product Master'!C2:C11,MATCH('Stock Data '!B24,'Product Master'!A2:A11,0)) -> 120 | I24: =IF(F24<20,"LOW STOCK","OK") -> OK
A25: 46360 | B25: P004 | C25: Biscuit | D25: 70 | E25: 20 | F25: =D25-E25 -> 50 | G25: =VLOOKUP(B25,'Product Master'!A2:C11,2,FALSE) -> Snacks | H25: =INDEX('Product Master'!C2:C11,MATCH('Stock Data '!B25,'Product Master'!A2:A11,0)) -> 30 | I25: =IF(F25<20,"LOW STOCK","OK") -> OK
A26: 46360 | B26: P005 | C26: Juice | D26: 55 | E26: 12 | F26: =D26-E26 -> 43 | G26: =VLOOKUP(B26,'Product Master'!A2:C11,2,FALSE) -> Beverages | H26: =INDEX('Product Master'!C2:C11,MATCH('Stock Data '!B26,'Product Master'!A2:A11,0)) -> 60 | I26: =IF(F26<20,"LOW STOCK","OK") -> OK
A27: 13/4/2026 | B27: P006 | C27: Soap | D27: 90 | E27: 30 | F27: =D27-E27 -> 60 | G27: =VLOOKUP(B27,'Product Master'!A2:C11,2,FALSE) -> Personal Care | H27: =INDEX('Product Master'!C2:C11,MATCH('Stock Data '!B27,'Product Master'!A2:A11,0)) -> 40 | I27: =IF(F27<20,"LOW STOCK","OK") -> OK
A28: 13/4/2026 | B28: P007 | C28: Shampoo | D28: 65 | E28: 22 | F28: =D28-E28 -> 43 | G28: =VLOOKUP(B28,'Product Master'!A2:C11,2,FALSE) -> Personal Care | H28: =INDEX('Product Master'!C2:C11,MATCH('Stock Data '!B28,'Product Master'!A2:A11,0)) -> 150 | I28: =IF(F28<20,"LOW STOCK","OK") -> OK
A29: 14/4/2026 | B29: P008 | C29: Tea | D29: 60 | E29: 15 | F29: =D29-E29 -> 45 | G29: =VLOOKUP(B29,'Product Master'!A2:C11,2,FALSE) -> Grocery | H29: =INDEX('Product Master'!C2:C11,MATCH('Stock Data '!B29,'Product Master'!A2:A11,0)) -> 200 | I29: =IF(F29<20,"LOW STOCK","OK") -> OK
A30: 14/4/2026 | B30: P009 | C30: Coffee | D30: 50 | E30: 10 | F30: =D30-E30 -> 40 | G30: =VLOOKUP(B30,'Product Master'!A2:C11,2,FALSE) -> Grocery | H30: =INDEX('Product Master'!C2:C11,MATCH('Stock Data '!B30,'Product Master'!A2:A11,0)) -> 250 | I30: =IF(F30<20,"LOW STOCK","OK") -> OK
A31: 15/4/2026 | B31: P010 | C31: Milk | D31: 85 | E31: 35 | F31: =D31-E31 -> 50 | G31: =VLOOKUP(B31,'Product Master'!A2:C11,2,FALSE) -> Dairy | H31: =INDEX('Product Master'!C2:C11,MATCH('Stock Data '!B31,'Product Master'!A2:A11,0)) -> 35 | I31: =IF(F31<20,"LOW STOCK","OK") -> OK
A32: 15/4/2026 | B32: P001 | C32: Rice | D32: 80 | E32: 20 | F32: =D32-E32 -> 60 | G32: =VLOOKUP(B32,'Product Master'!A2:C11,2,FALSE) -> Grocery | H32: =INDEX('Product Master'!C2:C11,MATCH('Stock Data '!B32,'Product Master'!A2:A11,0)) -> 50 | I32: =IF(F32<20,"LOW STOCK","OK") -> OK
A33: 16/4/2026 | B33: P002 | C33: Sugar | D33: 55 | E33: 15 | F33: =D33-E33 -> 40 | G33: =VLOOKUP(B33,'Product Master'!A2:C11,2,FALSE) -> Grocery | H33: =INDEX('Product Master'!C2:C11,MATCH('Stock Data '!B33,'Product Master'!A2:A11,0)) -> 45 | I33: =IF(F33<20,"LOW STOCK","OK") -> OK
A34: 16/4/2026 | B34: P003 | C34: Oil | D34: 40 | E34: 8 | F34: =D34-E34 -> 32 | G34: =VLOOKUP(B34,'Product Master'!A2:C11,2,FALSE) -> Grocery | H34: =INDEX('Product Master'!C2:C11,MATCH('Stock Data '!B34,'Product Master'!A2:A11,0)) -> 120 | I34: =IF(F34<20,"LOW STOCK","OK") -> OK
A35: 17/4/2026 | B35: P004 | C35: Biscuit | D35: 65 | E35: 18 | F35: =D35-E35 -> 47 | G35: =VLOOKUP(B35,'Product Master'!A2:C11,2,FALSE) -> Snacks | H35: =INDEX('Product Master'!C2:C11,MATCH('Stock Data '!B35,'Product Master'!A2:A11,0)) -> 30 | I35: =IF(F35<20,"LOW STOCK","OK") -> OK
A36: 17/4/2026 | B36: P005 | C36: Juice | D36: 50 | E36: 10 | F36: =D36-E36 -> 40 | G36: =VLOOKUP(B36,'Product Master'!A2:C11,2,FALSE) -> Beverages | H36: =INDEX('Product Master'!C2:C11,MATCH('Stock Data '!B36,'Product Master'!A2:A11,0)) -> 60 | I36: =IF(F36<20,"LOW STOCK","OK") -> OK
A37: 18/4/2026 | B37: P006 | C37: Soap | D37: 85 | E37: 25 | F37: =D37-E37 -> 60 | G37: =VLOOKUP(B37,'Product Master'!A2:C11,2,FALSE) -> Personal Care | H37: =INDEX('Product Master'!C2:C11,MATCH('Stock Data '!B37,'Product Master'!A2:A11,0)) -> 40 | I37: =IF(F37<20,"LOW STOCK","OK") -> OK
A38: 18/4/2026 | B38: P007 | C38: Shampoo | D38: 60 | E38: 18 | F38: =D38-E38 -> 42 | G38: =VLOOKUP(B38,'Product Master'!A2:C11,2,FALSE) -> Personal Care | H38: =INDEX('Product Master'!C2:C11,MATCH('Stock Data '!B38,'Product Master'!A2:A11,0)) -> 150 | I38: =IF(F38<20,"LOW STOCK","OK") -> OK
A39: 19/4/2026 | B39: P008 | C39: Tea | D39: 55 | E39: 12 | F39: =D39-E39 -> 43 | G39: =VLOOKUP(B39,'Product Master'!A2:C11,2,FALSE) -> Grocery | H39: =INDEX('Product Master'!C2:C11,MATCH('Stock Data '!B39,'Product Master'!A2:A11,0)) -> 200 | I39: =IF(F39<20,"LOW STOCK","OK") -> OK
A40: 19/4/2026 | B40: P009 | C40: Coffee | D40: 45 | E40: 8 | F40: =D40-E40 -> 37 | G40: =VLOOKUP(B40,'Product Master'!A2:C11,2,FALSE) -> Grocery | H40: =INDEX('Product Master'!C2:C11,MATCH('Stock Data '!B40,'Product Master'!A2:A11,0)) -> 250 | I40: =IF(F40<20,"LOW STOCK","OK") -> OK
...

Sheet PIVOT TABLE
B2: STOCK VALUE BY CATEGORY | D2: STOCK STATUS COUNT | F2: PRODUCT WISE STOCK
A3: Row Labels | B3: Sum of CURRENT STOCK | C3: Row Labels | D3: Count of STOCK STATUS | E3: Row Labels | F3: Sum of CURRENT STOCK
A4: Grocery | B4: 220 | C4: OK | D4: 5 | E4: Shampoo | F4: 42
A5: Grand Total | B5: 220 | C5: Grand Total | D5: 5 | E5: Grand Total | F5: 42

Sheet Product Master
A1: PRODUCT ID | B1: CATEGORY | C1: PRICE
A2: P001 | B2: Grocery | C2: 50
A3: P002 | B3: Grocery | C3: 45
A4: P003 | B4: Grocery | C4: 120
A5: P004 | B5: Snacks | C5: 30
A6: P005 | B6: Beverages | C6: 60
A7: P006 | B7: Personal Care | C7: 40
A8: P007 | B8: Personal Care | C8: 150
A9: P008 | B9: Grocery | C9: 200
A10: P009 | B10: Grocery | C10: 250
A11: P010 | B11: Dairy | C11: 35

Sheet MIS Report
A1: KPI
A2: TOTAL STOCK | B2: =COUNTA('Stock Data '!F2:F51) -> 50
A3: TOTAL STOCK VALUE | B3: =SUM('Stock Data '!F2:F51) -> 2459
A4: LOW STOCK COUNT | B4: 0
A5: TOTAL PRODUCTS | B5: =COUNTA('Stock Data '!C2:C51) -> 50
B26: STOCK VALUE BY CATEGORY SLICER | F26: STOCK STATUS COUNT SLICER | N26: PRODUCT WISE STOCK SLICER
