Workbook

Sheet Employee Data
A1: Emp ID | B1: Name | C1: Department | D1: Hours Worked | E1: Salary | F1: Bonus
A2: E001 | B2: Arun | C2: Sales | D2: 160 | E2: =VLOOKUP(C2,'Salary Master '!A2:B4,2,FALSE)*D2 -> 32000 | F2: =E2*HLOOKUP(C2,'Salary Master '!D1:G2,2,FALSE) -> 3200
A3: E002 | B3: Rahul | C3: IT | D3: 150 | E3: =VLOOKUP(C3,'Salary Master '!A3:B5,2,FALSE)*D3 -> 45000 | F3: =E3*HLOOKUP(C3,'Salary Master '!D1:G2,2,FALSE) -> 5400
A4: E003 | B4: Sneha | C4: HR | D4: 170 | E4: =VLOOKUP(C4,'Salary Master '!A4:B6,2,FALSE)*D4 -> 42500 | F4: =E4*HLOOKUP(C4,'Salary Master '!D1:G2,2,FALSE) -> 3400
A5: E004 | B5: Anu | C5: Sales | D5: 165 | E5: =VLOOKUP(C5,'Salary Master '!A2:B4,2)*D5 -> 41250 | F5: =E5*HLOOKUP(C5,'Salary Master '!D1:G2,2,FALSE) -> 4125
A6: E005 | B6: Manu | C6: IT | D6: 155 | E6: =VLOOKUP(C6,'Salary Master '!A3:B5,2)*D6 -> 38750 | F6: =E6*HLOOKUP(C6,'Salary Master '!D1:G2,2,FALSE) -> 4650
A7: E006 | B7: Riya | C7: HR | D7: 160 | E7: =VLOOKUP(C7,'Salary Master '!A4:B6,2)*D7 -> 40000 | F7: =E7*HLOOKUP(C7,'Salary Master '!D1:G2,2,FALSE) -> 3200
A8: E007 | B8: Akhil | C8: Sales | D8: 172 | E8: =VLOOKUP(C8,'Salary Master '!A2:B4,2)*D8 -> 43000 | F8: =E8*HLOOKUP(C8,'Salary Master '!D1:G2,2,FALSE) -> 4300
A9: E008 | B9: Neha | C9: IT | D9: 148 | E9: =VLOOKUP(C9,'Salary Master '!A3:B5,2)*D9 -> 37000 | F9: =E9*HLOOKUP(C9,'Salary Master '!D1:G2,2,FALSE) -> 4440
A10: E009 | B10: Vivek | C10: HR | D10: 169 | E10: =VLOOKUP(C10,'Salary Master '!A4:B6,2)*D10 -> 42250 | F10: =E10*HLOOKUP(C10,'Salary Master '!D1:G2,2,FALSE) -> 3380
A11: E010 | B11: Meera | C11: Sales | D11: 158 | E11: =VLOOKUP(C11,'Salary Master '!A2:B4,2)*D11 -> 39500 | F11: =E11*HLOOKUP(C11,'Salary Master '!D1:G2,2,FALSE) -> 3950
A12: E011 | B12: Kiran | C12: IT | D12: 162 | E12: =VLOOKUP(C12,'Salary Master '!A3:B5,2)*D12 -> 40500 | F12: =E12*HLOOKUP(C12,'Salary Master '!D1:G2,2,FALSE) -> 4860
A13: E012 | B13: Asha | C13: HR | D13: 151 | E13: =VLOOKUP(C13,'Salary Master '!A4:B6,2)*D13 -> 37750 | F13: =E13*HLOOKUP(C13,'Salary Master '!D1:G2,2,FALSE) -> 3020
A14: E013 | B14: Rohit | C14: Sales | D14: 175 | E14: =VLOOKUP(C14,'Salary Master '!A2:B4,2)*'Employee Data'!D14 -> 43750 | F14: =E14*HLOOKUP(C14,'Salary Master '!D1:G2,2,FALSE) -> 4375 | I14: 💻 PROJECT 2: Employee Salary MIS System
A15: E014 | B15: Pooja | C15: IT | D15: 149 | E15: =VLOOKUP(C15,'Salary Master '!A3:B5,2)*'Employee Data'!D15 -> 37250 | F15: =E15*HLOOKUP(C15,'Salary Master '!D1:G2,2,FALSE) -> 4470
A16: E015 | B16: Nikhil | C16: HR | D16: 168 | E16: =VLOOKUP(C16,'Salary Master '!A4:B6,2)*'Employee Data'!D16 -> 42000 | F16: =E16*HLOOKUP(C16,'Salary Master '!D1:G2,2,FALSE) -> 3360
A17: E016 | B17: Divya | C17: Sales | D17: 161 | E17: =VLOOKUP(C17,'Salary Master '!A2:B4,2)*'Employee Data'!D17 -> 40250 | F17: =E17*HLOOKUP(C17,'Salary Master '!D1:G2,2,FALSE) -> 4025
A18: E017 | B18: Sachin | C18: IT | D18: 153 | E18: =VLOOKUP(C18,'Salary Master '!A3:B5,2)*'Employee Data'!D18 -> 38250 | F18: =E18*HLOOKUP(C18,'Salary Master '!D1:G2,2,FALSE) -> 4590
A19: E018 | B19: Kavya | C19: HR | D19: 166 | E19: =VLOOKUP(C19,'Salary Master '!A4:B6,2)*'Employee Data'!D19 -> 41500 | F19: =E19*HLOOKUP(C19,'Salary Master '!D1:G2,2,FALSE) -> 3320
A20: E019 | B20: Anoop | C20: Sales | D20: 159 | E20: =VLOOKUP(C20,'Salary Master '!A2:B4,2)*D20 -> 39750 | F20: =E20*HLOOKUP(C20,'Salary Master '!D1:G2,2,FALSE) -> 3975
A21: E020 | B21: Anjali | C21: IT | D21: 150 | E21: =VLOOKUP(C21,'Salary Master '!A3:B5,2)*D21 -> 37500 | F21: =E21*HLOOKUP(C21,'Salary Master '!D1:G2,2,FALSE) -> 4500
A22: E021 | B22: Deepak | C22: HR | D22: 171 | E22: =VLOOKUP(C22,'Salary Master '!A4:B6,2)*D22 -> 42750 | F22: =E22*HLOOKUP(C22,'Salary Master '!D1:G2,2,FALSE) -> 3420
A23: E022 | B23: Reshma | C23: Sales | D23: 167 | E23: =VLOOKUP(C23,'Salary Master '!A2:B4,2)*'Employee Data'!D23 -> 41750 | F23: =E23*HLOOKUP(C23,'Salary Master '!D1:G2,2,FALSE) -> 4175
A24: E023 | B24: Varun | C24: IT | D24: 154 | E24: =VLOOKUP(C24,'Salary Master '!A3:B5,2)*'Employee Data'!D24 -> 38500 | F24: =E24*HLOOKUP(C24,'Salary Master '!D1:G2,2,FALSE) -> 4620
A25: E024 | B25: Anitha | C25: HR | D25: 165 | E25: =VLOOKUP(C25,'Salary Master '!A4:B6,2)*'Employee Data'!D25 -> 41250 | F25: =E25*HLOOKUP(C25,'Salary Master '!D1:G2,2,FALSE) -> 3300
A26: E025 | B26: Pradeep | C26: Sales | D26: 173 | E26: =VLOOKUP(C26,'Salary Master '!A2:B4,2)*D26 -> 43250 | F26: =E26*HLOOKUP(C26,'Salary Master '!D1:G2,2,FALSE) -> 4325
A27: E026 | B27: Lekha | C27: IT | D27: 147 | E27: =VLOOKUP(C27,'Salary Master '!A3:B5,2)*D27 -> 36750 | F27: =E27*HLOOKUP(C27,'Salary Master '!D1:G2,2,FALSE) -> 4410
A28: E027 | B28: Sunil | C28: HR | D28: 164 | E28: =VLOOKUP(C28,'Salary Master '!A4:B6,2)*D28 -> 41000 | F28: =E28*HLOOKUP(C28,'Salary Master '!D1:G2,2,FALSE) -> 3280
A29: E028 | B29: Gayathri | C29: Sales | D29: 160 | E29: =VLOOKUP(C29,'Salary Master '!A2:B4,2)*'Employee Data'!D29 -> 40000 | F29: =E29*HLOOKUP(C29,'Salary Master '!D1:G2,2,FALSE) -> 4000
A30: E029 | B30: Ajay | C30: IT | D30: 152 | E30: =VLOOKUP(C30,'Salary Master '!A3:B5,2)*'Employee Data'!D30 -> 38000 | F30: =E30*HLOOKUP(C30,'Salary Master '!D1:G2,2,FALSE) -> 4560
A31: E030 | B31: Nisha | C31: HR | D31: 169 | E31: =VLOOKUP(C31,'Salary Master '!A4:B6,2)*'Employee Data'!D31 -> 42250 | F31: =E31*HLOOKUP(C31,'Salary Master '!D1:G2,2,FALSE) -> 3380
A32: E031 | B32: Rakesh | C32: Sales | D32: 162 | E32: =VLOOKUP(C32,'Salary Master '!A2:B4,2)*D32 -> 40500 | F32: =E32*HLOOKUP(C32,'Salary Master '!D1:G2,2,FALSE) -> 4050
A33: E032 | B33: Maya | C33: IT | D33: 151 | E33: =VLOOKUP(C33,'Salary Master '!A3:B5,2)*D33 -> 37750 | F33: =E33*HLOOKUP(C33,'Salary Master '!D1:G2,2,FALSE) -> 4530
A34: E033 | B34: Suresh | C34: HR | D34: 170 | E34: =VLOOKUP(C34,'Salary Master '!A4:B6,2)*D34 -> 42500 | F34: =E34*HLOOKUP(C34,'Salary Master '!D1:G2,2,FALSE) -> 3400
A35: E034 | B35: Keerthi | C35: Sales | D35: 158 | E35: =VLOOKUP(C35,'Salary Master '!A2:B4,2)*D35 -> 39500 | F35: =E35*HLOOKUP(C35,'Salary Master '!D1:G2,2,FALSE) -> 3950
A36: E035 | B36: Biju | C36: IT | D36: 149 | E36: =VLOOKUP(C36,'Salary Master '!A3:B5,2)*D36 -> 37250 | F36: =E36*HLOOKUP(C36,'Salary Master '!D1:G2,2,FALSE) -> 4470
A37: E036 | B37: Ammu | C37: HR | D37: 167 | E37: =VLOOKUP(C37,'Salary Master '!A4:B6,2)*D37 -> 41750 | F37: =E37*HLOOKUP(C37,'Salary Master '!D1:G2,2,FALSE) -> 3340
A38: E037 | B38: Jithin | C38: Sales | D38: 174 | E38: =VLOOKUP(C38,'Salary Master '!A2:B4,2)*D38 -> 43500 | F38: =E38*HLOOKUP(C38,'Salary Master '!D1:G2,2,FALSE) -> 4350
A39: E038 | B39: Teena | C39: IT | D39: 155 | E39: =VLOOKUP(C39,'Salary Master '!A3:B5,2)*D39 -> 38750 | F39: =E39*HLOOKUP(C39,'Salary Master '!D1:G2,2,FALSE) -> 4650
A40: E039 | B40: Hari | C40: HR | D40: 168 | E40: =VLOOKUP(C40,'Salary Master '!A4:B6,2)*D40 -> 42000 | F40: =E40*HLOOKUP(C40,'Salary Master '!D1:G2,2,FALSE) -> 3360
...

Sheet Salary Master  
A1: Department | B1: Rate per Hour | C1: Vertical for VLOOKUP | D1: Departemnt | E1: Sales | F1: IT | G1: HR | H1: Horizontal for Hlookup
A2: Sales | B2: 200 | D2: Bonus | E2: 0.1 | F2: 0.12 | G2: 0.08
A3: IT | B3: 300
A4: HR | B4: 250

Sheet MIS Report
A1: KPI
A2: Total Salry | B2: =SUM('Employee Data'!E2:E51) -> 2011500
A3: Total Bonus | B3: =SUM('Employee Data'!F2:F51) -> 200910
F4: Department V/S Sum of Salary
A5: Row Labels | B5: Sum of Salary
A6: HR | B6: 664500
A7: IT | B7: 652500
A8: Sales | B8: 694500
A9: Grand Total | B9: 2011500
A21: Row Labels | B21: Sum of Bonus
A22: HR | B22: 53160 | F22: Department V/S Sum Of BOnus
A23: IT | B23: 78300
A24: Sales | B24: 69450
A25: Grand Total | B25: 200910
